import axiosInstance from "/src/pages/api/axiosInstance.js";

// Sign up a new user
export const signUp = async (mobileNumber, password) => {
  try {
    const response = await axiosInstance.post("/signUp", {
      mobileNumber,
      password,
    });
    if (response.data.verifyToken) {
      localStorage.setItem("token", response.data.verifyToken);
    }
    console.log(response?.data, "response");
    return response.data;
  } catch (error) {
    throw error.response
      ? error.response.data
      : new Error("An unexpected error occurred");
  }
};

// Resend OTP for sign-up
export const resendSignUpOtp = async (mobileNumber, userId) => {
  try {
    const response = await axiosInstance.put("/signUp", {
      mobileNumber,
      userId,
    });
    return response.data;
  } catch (error) {
    console.error("Error during OTP resend:", error);
    throw error.response
      ? error.response.data
      : new Error("An unexpected error occurred");
  }
};

// Verify OTP during sign-up
export const verifyOtp = async ({ mobileNumber, otp, token }) => {
  try {
    const response = await axiosInstance.post(
      "/verifyOtp",
      {
        mobileNumber,
        otp,
      },
      {
        headers: {
          VerifyToken: token,
        },
      }
    );
    return response?.data;
  } catch (error) {
    console.log("ðŸš€ ~ verifyOtp ~ error:", error);
    throw error.response
      ? error.response.data
      : new Error("An unexpected error occurred");
  }
};

// Sign in an existing user
export const signIn = async (mobileNumber, password) => {
  try {
    const response = await axiosInstance.post("/signIn", {
      mobileNumber,
      password,
    });
    console.log("first", response.data);
    if (response.data.authToken) {
      localStorage.setItem("token", response.data.authToken);
    }
    return response.data;
  } catch (error) {
    throw error.response
      ? new Error(
          error.response.data.message || "An error occurred during sign in"
        )
      : new Error("An unexpected error occurred");
  }
};

// forgot password
export const forgotPassword = async (mobileNumber) => {
  try {
    const response = await axiosInstance.post("/forgotPassword", {
      mobileNumber,
    });

    console.log("Password reset response:", response.data);

    return response.data;
  } catch (error) {
    // Handle errors
    throw error.response
      ? new Error(
          error.response.data.message ||
            "An error occurred during the password reset process"
        )
      : new Error("An unexpected error occurred");
  }
};

//forgot password otp verification
export const verifyForgotPasswordOtp = async ({ mobileNumber, otp, token }) => {
  try {
    const response = await axiosInstance.post(
      "/verify/forgotPasswordOTP",
      { mobileNumber, otp },
      {
        headers: {
          VerifyFPToken: token,
        },
      }
    );
    return response?.data;
  } catch (error) {
    console.log("ðŸš€ ~ verifyForgotPasswordOtp ~ error:", error);
    throw error.response
      ? error.response.data
      : new Error("An unexpected error occurred");
  }
};

//create new password
export const resetPassword = async (mobileNumber, newPassword) => {
  try {
    const response = await axiosInstance.put("/forgotPassword", {
      mobileNumber,
      password: newPassword,
    });
    return response.data;
  } catch (error) {
    console.error("Error during password reset:", error);
    throw error.response
      ? error.response.data
      : new Error("An unexpected error occurred");
  }
};